<?xml version="1.0" encoding="utf-8"?>
<!-- This URDF was automatically created by SolidWorks to URDF Exporter! Originally created by Stephen Brawner (brawner@gmail.com) 
     Commit Version: 1.5.1-0-g916b5db  Build Version: 1.5.7152.31018
     For more information, please see http://wiki.ros.org/sw_urdf_exporter -->
<robot
  name="husky">H = massMatrix(robot)
  <link
    name="Body">
    <inertial>
      <origin
        xyz="0.021107 -5.5457E-05 -0.041523"
        rpy="0 0 0" />
      <mass
        value="0.82235" />
      <inertia
        ixx="0.00045992"
        ixy="8.2923E-13"
        ixz="1.9642E-05"
        iyy="0.00054448"
        iyz="3.0755E-08"
        izz="0.00032373" />
    </inertial>
    <visual>
      <origin
        xyz="0 0 0"
        rpy="0 0 0" />
      <geometry>
        <mesh
          filename="package://husky/meshes/Body.STL" />
      </geometry>
      <material
        name="">
        <color
          rgba="1 1 1 1" />
      </material>
    </visual>
    <collision>
      <origin
        xyz="0 0 0"
        rpy="0 0 0" />
      <geometry>
        <mesh
          filename="package://husky/meshes/Body.STL" />
      </geometry>
    </collision>
  </link>
  <link
    name="hip_rl">
    <inertial>
      <origin
        xyz="0.024751 -0.0025459 -6.0284E-05"
        rpy="0 0 0" />
      <mass
        value="0.035944" />
      <inertia
        ixx="9.4368E-06"
        ixy="2.3932E-06"
        ixz="-7.3784E-08"
        iyy="2.7076E-05"
        iyz="5.0995E-09"
        izz="2.4422E-05" />
    </inertial>
    <visual>
      <origin
        xyz="0 0 0"
        rpy="0 0 0" />
      <geometry>
        <mesh
          filename="package://husky/meshes/hip_rl.STL" />
      </geometry>
      <material
        name="">
        <color
          rgba="1 0 0 1" />
      </material>
    </visual>
    <collision>
      <origin
        xyz="0 0 0"
        rpy="0 0 0" />
      <geometry>
        <mesh
          filename="package://husky/meshes/hip_rl.STL" />
      </geometry>
    </collision>
  </link>
  <joint
    name="hip_rl_ab"
    type="revolute">
    <origin
      xyz="-0.19745 0.045 0"
      rpy="0 0 0" />
    <parent
      link="Body" />
    <child
      link="hip_rl" />
    <axis
      xyz="-1 0 0" />
    <limit
      lower="-3.14"
      upper="3.14"
      effort="1000"
      velocity="1000" />
  </joint>
  <link
    name="femur_rl">
    <inertial>
      <origin
        xyz="-2.704E-07 0.036112 -0.082829"
        rpy="0 0 0" />
      <mass
        value="0.1521" />
      <inertia
        ixx="4.3927E-05"
        ixy="6.9154E-10"
        ixz="-1.8319E-08"
        iyy="6.2109E-05"
        iyz="4.5878E-10"
        izz="2.7563E-05" />
    </inertial>
    <visual>
      <origin
        xyz="0 0 0"
        rpy="0 0 0" />
      <geometry>
        <mesh
          filename="package://husky/meshes/femur_rl.STL" />
      </geometry>
      <material
        name="">
        <color
          rgba="0 1 0 1" />
      </material>
    </visual>
    <collision>
      <origin
        xyz="0 0 0"
        rpy="0 0 0" />
      <geometry>
        <mesh
          filename="package://husky/meshes/femur_rl.STL" />
      </geometry>
    </collision>
  </link>
  <joint
    name="hip_rl_ex"
    type="revolute">
    <origin
      xyz="0.053 -0.007 0"
      rpy="0 0 0" />
    <parent
      link="hip_rl" />
    <child
      link="femur_rl" />
    <axis
      xyz="0 1 0" />
    <limit
      lower="-3.14"
      upper="3.14"
      effort="1000"
      velocity="1000" />
  </joint>
  <link
    name="tibia_rl">
    <inertial>
      <origin
        xyz="-0.10575 0.0039831 1.084E-05"
        rpy="0 0 0" />
      <mass
        value="0.038628" />
      <inertia
        ixx="7.1252E-06"
        ixy="1.0931E-06"
        ixz="-8.0061E-10"
        iyy="3.484E-05"
        iyz="-1.6386E-09"
        izz="2.9866E-05" />
    </inertial>
    <visual>
      <origin
        xyz="0 0 0"
        rpy="0 0 0" />
      <geometry>
        <mesh
          filename="package://husky/meshes/tibia_rl.STL" />
      </geometry>
      <material
        name="">
        <color
          rgba="0 0 1 1" />
      </material>
    </visual>
    <collision>
      <origin
        xyz="0 0 0"
        rpy="0 0 0" />
      <geometry>
        <mesh
          filename="package://husky/meshes/tibia_rl.STL" />
      </geometry>
    </collision>
  </link>
  <joint
    name="knee_rl"
    type="revolute">
    <origin
      xyz="0 0 -0.158"
      rpy="0 0 0" />
    <parent
      link="femur_rl" />
    <child
      link="tibia_rl" />
    <axis
      xyz="0 -1 0" />
    <limit
      lower="-3.14"
      upper="3.14"
      effort="1000"
      velocity="1000" />
  </joint>
  <link
    name="tarsus_rl">
    <inertial>
      <origin
        xyz="3.6446E-11 2.4923E-10 -0.054555"
        rpy="0 0 0" />
      <mass
        value="0.18284" />
      <inertia
        ixx="0.00012076"
        ixy="-8.5139E-12"
        ixz="-6.9478E-13"
        iyy="0.00011699"
        iyz="3.7744E-12"
        izz="2.5133E-05" />
    </inertial>
    <visual>
      <origin
        xyz="0 0 0"
        rpy="0 0 0" />
      <geometry>
        <mesh
          filename="package://husky/meshes/tarsus_rl.STL" />
      </geometry>
      <material
        name="">
        <color
          rgba="0.5 0.5 1 1" />
      </material>
    </visual>
    <collision>
      <origin
        xyz="0 0 0"
        rpy="0 0 0" />
      <geometry>
        <mesh
          filename="package://husky/meshes/tarsus_rl.STL" />
      </geometry>
    </collision>
  </link>
  <joint
    name="ankle_rl"
    type="revolute">
    <origin
      xyz="-0.333 0.0075 0"
      rpy="0 0 0" />
    <parent
      link="tibia_rl" />
    <child
      link="tarsus_rl" />
    <axis
      xyz="0 -1 0" />
    <limit
      lower="-3.14"
      upper="3.14"
      effort="1000"
      velocity="1000" />
  </joint>
  <link
    name="hip_rr">
    <inertial>
      <origin
        xyz="0.024751 0.0025459 6.0284E-05"
        rpy="0 0 0" />
      <mass
        value="0.035944" />
      <inertia
        ixx="9.4368E-06"
        ixy="-2.3932E-06"
        ixz="7.3784E-08"
        iyy="2.7076E-05"
        iyz="5.0995E-09"
        izz="2.4422E-05" />
    </inertial>
    <visual>
      <origin
        xyz="0 0 0"
        rpy="0 0 0" />
      <geometry>
        <mesh
          filename="package://husky/meshes/hip_rr.STL" />
      </geometry>
      <material
        name="">
        <color
          rgba="1 0 0 1" />
      </material>
    </visual>
    <collision>
      <origin
        xyz="0 0 0"
        rpy="0 0 0" />
      <geometry>
        <mesh
          filename="package://husky/meshes/hip_rr.STL" />
      </geometry>
    </collision>
  </link>
  <joint
    name="hip_rr_ab"
    type="revolute">
    <origin
      xyz="-0.19745 -0.045 0"
      rpy="0 0 0" />
    <parent
      link="Body" />
    <child
      link="hip_rr" />
    <axis
      xyz="-1 0 0" />
    <limit
      lower="-3.14"
      upper="3.14"
      effort="1000"
      velocity="1000" />
  </joint>
  <link
    name="femur_rr">
    <inertial>
      <origin
        xyz="2.704E-07 -0.036112 -0.082829"
        rpy="0 0 0" />
      <mass
        value="0.1521" />
      <inertia
        ixx="4.3927E-05"
        ixy="6.9154E-10"
        ixz="1.8319E-08"
        iyy="6.2109E-05"
        iyz="-4.5879E-10"
        izz="2.7563E-05" />
    </inertial>
    <visual>
      <origin
        xyz="0 0 0"
        rpy="0 0 0" />
      <geometry>
        <mesh
          filename="package://husky/meshes/femur_rr.STL" />
      </geometry>
      <material
        name="">
        <color
          rgba="0 1 0 1" />
      </material>
    </visual>
    <collision>
      <origin
        xyz="0 0 0"
        rpy="0 0 0" />
      <geometry>
        <mesh
          filename="package://husky/meshes/femur_rr.STL" />
      </geometry>
    </collision>
  </link>
  <joint
    name="hip_rr_ex"
    type="revolute">
    <origin
      xyz="0.053 0.007 0"
      rpy="0 0 0" />
    <parent
      link="hip_rr" />
    <child
      link="femur_rr" />
    <axis
      xyz="0 -1 0" />
    <limit
      lower="-3.14"
      upper="3.14"
      effort="1000"
      velocity="1000" />
  </joint>
  <link
    name="tibia_rr">
    <inertial>
      <origin
        xyz="-0.10575 -0.0039831 -1.084E-05"
        rpy="0 0 0" />
      <mass
        value="0.038628" />
      <inertia
        ixx="7.1252E-06"
        ixy="-1.0931E-06"
        ixz="8.0091E-10"
        iyy="3.484E-05"
        iyz="-1.6386E-09"
        izz="2.9866E-05" />
    </inertial>
    <visual>
      <origin
        xyz="0 0 0"
        rpy="0 0 0" />
      <geometry>
        <mesh
          filename="package://husky/meshes/tibia_rr.STL" />
      </geometry>
      <material
        name="">
        <color
          rgba="0 0 1 1" />
      </material>
    </visual>
    <collision>
      <origin
        xyz="0 0 0"
        rpy="0 0 0" />
      <geometry>
        <mesh
          filename="package://husky/meshes/tibia_rr.STL" />
      </geometry>
    </collision>
  </link>
  <joint
    name="knee_rr"
    type="revolute">
    <origin
      xyz="0 0 -0.158"
      rpy="0 0 0" />
    <parent
      link="femur_rr" />
    <child
      link="tibia_rr" />
    <axis
      xyz="0 1 0" />
    <limit
      lower="-3.14"
      upper="3.14"
      effort="1000"
      velocity="1000" />
  </joint>
  <link
    name="tarsus_rr">
    <inertial>
      <origin
        xyz="-3.6453E-11 -2.4587E-10 -0.054555"
        rpy="0 0 0" />
      <mass
        value="0.18284" />
      <inertia
        ixx="0.00012076"
        ixy="-8.5139E-12"
        ixz="6.9478E-13"
        iyy="0.00011699"
        iyz="-3.7744E-12"
        izz="2.5133E-05" />
    </inertial>
    <visual>
      <origin
        xyz="0 0 0"
        rpy="0 0 0" />
      <geometry>
        <mesh
          filename="package://husky/meshes/tarsus_rr.STL" />
      </geometry>
      <material
        name="">
        <color
          rgba="0.5 0.5 1 1" />
      </material>
    </visual>
    <collision>
      <origin
        xyz="0 0 0"
        rpy="0 0 0" />
      <geometry>
        <mesh
          filename="package://husky/meshes/tarsus_rr.STL" />
      </geometry>
    </collision>
  </link>
  <joint
    name="ankle_rr"
    type="revolute">
    <origin
      xyz="-0.333 -0.0075 0"
      rpy="0 0 0" />
    <parent
      link="tibia_rr" />
    <child
      link="tarsus_rr" />
    <axis
      xyz="0 1 0" />
    <limit
      lower="-3.14"
      upper="3.14"
      effort="1000"
      velocity="1000" />
  </joint>
  <link
    name="hip_fl">
    <inertial>
      <origin
        xyz="0.024751 -0.0025459 -6.0284E-05"
        rpy="0 0 0" />
      <mass
        value="0.035944" />
      <inertia
        ixx="9.4368E-06"
        ixy="2.3932E-06"
        ixz="-7.3784E-08"
        iyy="2.7076E-05"
        iyz="5.0995E-09"
        izz="2.4422E-05" />
    </inertial>
    <visual>
      <origin
        xyz="0 0 0"
        rpy="0 0 0" />
      <geometry>
        <mesh
          filename="package://husky/meshes/hip_fl.STL" />
      </geometry>
      <material
        name="">
        <color
          rgba="1 0 0 1" />
      </material>
    </visual>
    <collision>
      <origin
        xyz="0 0 0"
        rpy="0 0 0" />
      <geometry>
        <mesh
          filename="package://husky/meshes/hip_fl.STL" />
      </geometry>
    </collision>
  </link>
  <joint
    name="hip_fl_ab"
    type="revolute">
    <origin
      xyz="0.19745 0.045 0"
      rpy="0 0 0" />
    <parent
      link="Body" />
    <child
      link="hip_fl" />
    <axis
      xyz="-1 0 0" />
    <limit
      lower="-3.14"
      upper="3.14"
      effort="1000"
      velocity="1000" />
  </joint>
  <link
    name="femur_fl">
    <inertial>
      <origin
        xyz="-2.7039E-07 0.036112 -0.082829"
        rpy="0 0 0" />
      <mass
        value="0.1521" />
      <inertia
        ixx="4.3927E-05"
        ixy="6.9154E-10"
        ixz="-1.8319E-08"
        iyy="6.2109E-05"
        iyz="4.5877E-10"
        izz="2.7563E-05" />
    </inertial>
    <visual>
      <origin
        xyz="0 0 0"
        rpy="0 0 0" />
      <geometry>
        <mesh
          filename="package://husky/meshes/femur_fl.STL" />
      </geometry>
      <material
        name="">
        <color
          rgba="0 1 0 1" />
      </material>
    </visual>
    <collision>
      <origin
        xyz="0 0 0"
        rpy="0 0 0" />
      <geometry>
        <mesh
          filename="package://husky/meshes/femur_fl.STL" />
      </geometry>
    </collision>
  </link>
  <joint
    name="hip_fl_ex"
    type="revolute">
    <origin
      xyz="0.053 -0.007 0"
      rpy="0 0 0" />
    <parent
      link="hip_fl" />
    <child
      link="femur_fl" />
    <axis
      xyz="0 1 0" />
    <limit
      lower="-3.14"
      upper="3.14"
      effort="1000"
      velocity="1000" />
  </joint>
  <link
    name="tibia_fl">
    <inertial>
      <origin
        xyz="-0.10575 0.0039831 1.084E-05"
        rpy="0 0 0" />
      <mass
        value="0.038628" />
      <inertia
        ixx="7.1252E-06"
        ixy="1.0931E-06"
        ixz="-8.0093E-10"
        iyy="3.484E-05"
        iyz="-1.6386E-09"
        izz="2.9866E-05" />
    </inertial>
    <visual>
      <origin
        xyz="0 0 0"
        rpy="0 0 0" />
      <geometry>
        <mesh
          filename="package://husky/meshes/tibia_fl.STL" />
      </geometry>
      <material
        name="">
        <color
          rgba="0 0 1 1" />
      </material>
    </visual>
    <collision>
      <origin
        xyz="0 0 0"
        rpy="0 0 0" />
      <geometry>
        <mesh
          filename="package://husky/meshes/tibia_fl.STL" />
      </geometry>
    </collision>
  </link>
  <joint
    name="knee_fl"
    type="revolute">
    <origin
      xyz="0 0 -0.158"
      rpy="0 0 0" />
    <parent
      link="femur_fl" />
    <child
      link="tibia_fl" />
    <axis
      xyz="0 -1 0" />
    <limit
      lower="-3.14"
      upper="3.14"
      effort="1000"
      velocity="1000" />
  </joint>
  <link
    name="tarsus_fl">
    <inertial>
      <origin
        xyz="-3.6453E-11 -2.4587E-10 -0.054555"
        rpy="0 0 0" />
      <mass
        value="0.18284" />
      <inertia
        ixx="0.00012076"
        ixy="-8.5139E-12"
        ixz="6.9478E-13"
        iyy="0.00011699"
        iyz="-3.7744E-12"
        izz="2.5133E-05" />
    </inertial>
    <visual>
      <origin
        xyz="0 0 0"
        rpy="0 0 0" />
      <geometry>
        <mesh
          filename="package://husky/meshes/tarsus_fl.STL" />
      </geometry>
      <material
        name="">
        <color
          rgba="0.5 0.5 1 1" />
      </material>
    </visual>
    <collision>
      <origin
        xyz="0 0 0"
        rpy="0 0 0" />
      <geometry>
        <mesh
          filename="package://husky/meshes/tarsus_fl.STL" />
      </geometry>
    </collision>
  </link>
  <joint
    name="ankle_fl"
    type="revolute">
    <origin
      xyz="-0.333 0.006 0"
      rpy="0 0 0" />
    <parent
      link="tibia_fl" />
    <child
      link="tarsus_fl" />
    <axis
      xyz="0 1 0" />
    <limit
      lower="-3.14"
      upper="3.14"
      effort="1000"
      velocity="1000" />
  </joint>
  <link
    name="hip_fr">
    <inertial>
      <origin
        xyz="0.024751 0.0025459 6.0284E-05"
        rpy="0 0 0" />
      <mass
        value="0.03503" />
      <inertia
        ixx="9.1969E-06"
        ixy="-2.3323E-06"
        ixz="7.1908E-08"
        iyy="2.6388E-05"
        iyz="4.9699E-09"
        izz="2.3801E-05" />
    </inertial>
    <visual>
      <origin
        xyz="0 0 0"
        rpy="0 0 0" />
      <geometry>
        <mesh
          filename="package://husky/meshes/hip_fr.STL" />
      </geometry>
      <material
        name="">
        <color
          rgba="1 0 0 1" />
      </material>
    </visual>
    <collision>
      <origin
        xyz="0 0 0"
        rpy="0 0 0" />
      <geometry>
        <mesh
          filename="package://husky/meshes/hip_fr.STL" />
      </geometry>
    </collision>
  </link>
  <joint
    name="hip_fr_ab"
    type="revolute">
    <origin
      xyz="0.19745 -0.045 0"
      rpy="0 0 0" />
    <parent
      link="Body" />
    <child
      link="hip_fr" />
    <axis
      xyz="-1 0 0" />
    <limit
      lower="-3.14"
      upper="3.14"
      effort="1000"
      velocity="1000" />
  </joint>
  <link
    name="femur_fr">
    <inertial>
      <origin
        xyz="2.7041E-07 -0.036112 -0.082829"
        rpy="0 0 0" />
      <mass
        value="0.41066" />
      <inertia
        ixx="0.0001186"
        ixy="1.8672E-09"
        ixz="4.946E-08"
        iyy="0.0001677"
        iyz="-1.2387E-09"
        izz="7.442E-05" />
    </inertial>
    <visual>
      <origin
        xyz="0 0 0"
        rpy="0 0 0" />
      <geometry>
        <mesh
          filename="package://husky/meshes/femur_fr.STL" />
      </geometry>
      <material
        name="">
        <color
          rgba="0 1 0 1" />
      </material>
    </visual>
    <collision>
      <origin
        xyz="0 0 0"
        rpy="0 0 0" />
      <geometry>
        <mesh
          filename="package://husky/meshes/femur_fr.STL" />
      </geometry>
    </collision>
  </link>
  <joint
    name="hip_fr_ex"
    type="revolute">
    <origin
      xyz="0.053 0.007 0"
      rpy="0 0 0" />
    <parent
      link="hip_fr" />
    <child
      link="femur_fr" />
    <axis
      xyz="0 1 0" />
    <limit
      lower="-3.14"
      upper="3.14"
      effort="1000"
      velocity="1000" />
  </joint>
  <link
    name="tibia_fr">
    <inertial>
      <origin
        xyz="-0.10575 -0.0039831 -1.0841E-05"
        rpy="0 0 0" />
      <mass
        value="0.038628" />
      <inertia
        ixx="7.1252E-06"
        ixy="-1.0931E-06"
        ixz="8.012E-10"
        iyy="3.484E-05"
        iyz="-1.6385E-09"
        izz="2.9866E-05" />
    </inertial>
    <visual>
      <origin
        xyz="0 0 0"
        rpy="0 0 0" />
      <geometry>
        <mesh
          filename="package://husky/meshes/tibia_fr.STL" />
      </geometry>
      <material
        name="">
        <color
          rgba="0 0 1 1" />
      </material>
    </visual>
    <collision>
      <origin
        xyz="0 0 0"
        rpy="0 0 0" />
      <geometry>
        <mesh
          filename="package://husky/meshes/tibia_fr.STL" />
      </geometry>
    </collision>
  </link>
  <joint
    name="knee_fr"
    type="revolute">
    <origin
      xyz="0 0 -0.158"
      rpy="0 0 0" />
    <parent
      link="femur_fr" />
    <child
      link="tibia_fr" />
    <axis
      xyz="0 1 0" />
    <limit
      lower="-3.14"
      upper="3.14"
      effort="1000"
      velocity="1000" />
  </joint>
  <link
    name="tarsus_fr">
    <inertial>
      <origin
        xyz="3.6446E-11 2.4923E-10 -0.054555"
        rpy="0 0 0" />
      <mass
        value="0.18284" />
      <inertia
        ixx="0.00012076"
        ixy="-8.5139E-12"
        ixz="-6.9478E-13"
        iyy="0.00011699"
        iyz="3.7744E-12"
        izz="2.5133E-05" />
    </inertial>
    <visual>
      <origin
        xyz="0 0 0"
        rpy="0 0 0" />
      <geometry>
        <mesh
          filename="package://husky/meshes/tarsus_fr.STL" />
      </geometry>
      <material
        name="">
        <color
          rgba="0.5 0.5 1 1" />
      </material>
    </visual>
    <collision>
      <origin
        xyz="0 0 0"
        rpy="0 0 0" />
      <geometry>
        <mesh
          filename="package://husky/meshes/tarsus_fr.STL" />
      </geometry>
    </collision>
  </link>
  <joint
    name="ankle_fr"
    type="revolute">
    <origin
      xyz="-0.333 -0.007 0"
      rpy="0 0 0" />
    <parent
      link="tibia_fr" />
    <child
      link="tarsus_fr" />
    <axis
      xyz="0 -1 0" />
    <limit
      lower="-3.14"
      upper="3.14"
      effort="1000"
      velocity="1000" />
  </joint>
</robot>